# Translations template for cinder.
# Copyright (C) 2015 ORGANIZATION
# This file is distributed under the same license as the cinder project.
# FIRST AUTHOR <EMAIL@ADDRESS>, 2015.
#
#, fuzzy
msgid ""
msgstr ""
"Project-Id-Version: cinder 2015.1.dev303\n"
"Report-Msgid-Bugs-To: EMAIL@ADDRESS\n"
"POT-Creation-Date: 2015-01-30 06:25+0000\n"
"PO-Revision-Date: YEAR-MO-DA HO:MI+ZONE\n"
"Last-Translator: FULL NAME <EMAIL@ADDRESS>\n"
"Language-Team: LANGUAGE <LL@li.org>\n"
"MIME-Version: 1.0\n"
"Content-Type: text/plain; charset=utf-8\n"
"Content-Transfer-Encoding: 8bit\n"
"Generated-By: Babel 1.3\n"

#: cinder/exception.py:94
msgid "Exception in string format operation"
msgstr ""

#: cinder/quota.py:783
#, python-format
msgid "Failed to commit reservations %s"
msgstr ""

#: cinder/quota.py:804
#, python-format
msgid "Failed to roll back reservations %s"
msgstr ""

#: cinder/utils.py:618
#, python-format
msgid "Volume driver %s not initialized"
msgstr ""

#: cinder/wsgi.py:234
#, python-format
msgid "Failed to start %(name)s on %(_host)s:%(_port)s with SSL support."
msgstr ""

#: cinder/api/extensions.py:244
#, python-format
msgid "Exception loading extension: %s"
msgstr ""

#: cinder/api/middleware/fault.py:46
#, python-format
msgid "Caught error: %s"
msgstr ""

#: cinder/api/openstack/wsgi.py:754
#, python-format
msgid "Exception handling resource: %s"
msgstr ""

#: cinder/backup/driver.py:200
#, python-format
msgid "The source volume type '%s' is not available."
msgstr ""

#: cinder/backup/driver.py:215
#, python-format
msgid ""
"The source volume type '%(src)s' is different than the destination volume"
" type '%(dest)s'."
msgstr ""

#: cinder/backup/manager.py:176
#, python-format
msgid "Error encountered during initialization of driver: %(name)s."
msgstr ""

#: cinder/backup/manager.py:452
msgid "Failed to update usages deleting backup"
msgstr ""

#: cinder/backup/manager.py:647
msgid "Backup driver has not been initialized"
msgstr ""

#: cinder/backup/drivers/ceph.py:460
#, python-format
msgid ""
"Max retries reached deleting backup %(basename)s image of volume "
"%(volume)s."
msgstr ""

#: cinder/backup/drivers/ceph.py:496
#, python-format
msgid "Pipe1 failed - %s "
msgstr ""

#: cinder/backup/drivers/ceph.py:510
#, python-format
msgid "Pipe2 failed - %s "
msgstr ""

#: cinder/backup/drivers/ceph.py:974
msgid "Differential restore failed, trying full restore"
msgstr ""

#: cinder/backup/drivers/ceph.py:1176
#, python-format
msgid "Restore to volume %(volume)s finished with error - %(error)s."
msgstr ""

#: cinder/backup/drivers/swift.py:171
#, python-format
msgid "single_user auth mode enabled, but %(param)s not set"
msgstr ""

#: cinder/backup/drivers/swift.py:459
#, python-format
msgid "Backup volume metadata to swift failed: %s"
msgstr ""

#: cinder/backup/drivers/tsm.py:252
#, python-format
msgid ""
"backup: %(vol_id)s failed to remove backup hardlink from %(vpath)s to "
"%(bpath)s.\n"
"stdout: %(out)s\n"
" stderr: %(err)s."
msgstr ""

#: cinder/backup/drivers/tsm.py:531
#, python-format
msgid ""
"delete: %(vol_id)s failed with stdout: %(out)s\n"
" stderr: %(err)s"
msgstr ""

#: cinder/brick/initiator/connector.py:148
#, python-format
msgid "Failed to access the device on the path %(path)s: %(error)s %(info)s."
msgstr ""

#: cinder/brick/initiator/connector.py:958
msgid "SDS CLI file not found, HuaweiStorHyperConnector init failed."
msgstr ""

#: cinder/brick/initiator/connector.py:1032
#, python-format
msgid "SDS CLI output some log: %s."
msgstr ""

#: cinder/brick/local_dev/lvm.py:79
msgid "Error creating Volume Group"
msgstr ""

#: cinder/brick/local_dev/lvm.py:80 cinder/brick/local_dev/lvm.py:162
#: cinder/brick/local_dev/lvm.py:546 cinder/brick/local_dev/lvm.py:577
#: cinder/brick/local_dev/lvm.py:620 cinder/brick/local_dev/lvm.py:701
#: cinder/brick/local_dev/lvm.py:739 cinder/volume/drivers/srb.py:124
#: cinder/volume/drivers/srb.py:144 cinder/volume/drivers/srb.py:162
#: cinder/volume/drivers/srb.py:180 cinder/volume/drivers/srb.py:206
#, python-format
msgid "Cmd     :%s"
msgstr ""

#: cinder/brick/local_dev/lvm.py:81 cinder/brick/local_dev/lvm.py:163
#: cinder/brick/local_dev/lvm.py:547 cinder/brick/local_dev/lvm.py:578
#: cinder/brick/local_dev/lvm.py:621 cinder/brick/local_dev/lvm.py:702
#: cinder/brick/local_dev/lvm.py:740 cinder/volume/drivers/srb.py:125
#: cinder/volume/drivers/srb.py:145 cinder/volume/drivers/srb.py:163
#: cinder/volume/drivers/srb.py:181 cinder/volume/drivers/srb.py:207
#, python-format
msgid "StdOut  :%s"
msgstr ""

#: cinder/brick/local_dev/lvm.py:82 cinder/brick/local_dev/lvm.py:164
#: cinder/brick/local_dev/lvm.py:548 cinder/brick/local_dev/lvm.py:579
#: cinder/brick/local_dev/lvm.py:622 cinder/brick/local_dev/lvm.py:703
#: cinder/brick/local_dev/lvm.py:741 cinder/volume/drivers/srb.py:126
#: cinder/volume/drivers/srb.py:146 cinder/volume/drivers/srb.py:164
#: cinder/volume/drivers/srb.py:182 cinder/volume/drivers/srb.py:208
#, python-format
msgid "StdErr  :%s"
msgstr ""

#: cinder/brick/local_dev/lvm.py:86
#, python-format
msgid "Unable to locate Volume Group %s"
msgstr ""

#: cinder/brick/local_dev/lvm.py:161
msgid "Error querying thin pool about data_percent"
msgstr ""

#: cinder/brick/local_dev/lvm.py:401
#, python-format
msgid "Unable to find VG: %s"
msgstr ""

#: cinder/brick/local_dev/lvm.py:488
msgid ""
"Requested to setup thin provisioning, however current LVM version does "
"not support it."
msgstr ""

#: cinder/brick/local_dev/lvm.py:545
msgid "Error creating Volume"
msgstr ""

#: cinder/brick/local_dev/lvm.py:562
#, python-format
msgid "Trying to create snapshot by non-existent LV: %s"
msgstr ""

#: cinder/brick/local_dev/lvm.py:576
msgid "Error creating snapshot"
msgstr ""

#: cinder/brick/local_dev/lvm.py:619
msgid "Error activating LV"
msgstr ""

#: cinder/brick/local_dev/lvm.py:700
msgid "Error extending Volume"
msgstr ""

#: cinder/brick/local_dev/lvm.py:738
msgid "Error renaming logical volume"
msgstr ""

#: cinder/cmd/all.py:66
msgid "Failed to load osapi_volume"
msgstr ""

#: cinder/cmd/all.py:72
#, python-format
msgid "Failed to load %s"
msgstr ""

#: cinder/cmd/volume_usage_audit.py:123
#, python-format
msgid "Failed to send exists notification for volume %s."
msgstr ""

#: cinder/cmd/volume_usage_audit.py:151
#, python-format
msgid "Failed to send create notification for volume %s."
msgstr ""

#: cinder/cmd/volume_usage_audit.py:178
#, python-format
msgid "Failed to send delete notification for volume %s."
msgstr ""

#: cinder/cmd/volume_usage_audit.py:198
#, python-format
msgid "Failed to send exists notification for snapshot %s."
msgstr ""

#: cinder/cmd/volume_usage_audit.py:226
#, python-format
msgid "Failed to send create notification for snapshot%s."
msgstr ""

#: cinder/cmd/volume_usage_audit.py:253
#, python-format
msgid "Failed to send delete notification for snapshot%s."
msgstr ""

#: cinder/consistencygroup/api.py:139
#, python-format
msgid "Error occurred when creating consistency group %s."
msgstr ""

#: cinder/consistencygroup/api.py:202
#, python-format
msgid "Error occurred when building request spec list for consistency group %s."
msgstr ""

#: cinder/consistencygroup/api.py:229
#, python-format
msgid "Failed to update quota for consistency group %s."
msgstr ""

#: cinder/consistencygroup/api.py:371
#, python-format
msgid "Error occurred when creating cgsnapshot %s."
msgstr ""

#: cinder/db/sqlalchemy/migrate_repo/versions/002_quota_class.py:50
#: cinder/db/sqlalchemy/migrate_repo/versions/002_quota_class.py:75
#: cinder/db/sqlalchemy/migrate_repo/versions/002_quota_class.py:106
#, python-format
msgid "Table |%s| not created!"
msgstr ""

#: cinder/db/sqlalchemy/migrate_repo/versions/002_quota_class.py:135
#, python-format
msgid "Dropping foreign key %s failed."
msgstr ""

#: cinder/db/sqlalchemy/migrate_repo/versions/002_quota_class.py:142
msgid "quota_classes table not dropped"
msgstr ""

#: cinder/db/sqlalchemy/migrate_repo/versions/002_quota_class.py:149
msgid "quota_usages table not dropped"
msgstr ""

#: cinder/db/sqlalchemy/migrate_repo/versions/002_quota_class.py:156
msgid "reservations table not dropped"
msgstr ""

#: cinder/db/sqlalchemy/migrate_repo/versions/015_drop_migrations_table.py:32
msgid "migrations table not dropped"
msgstr ""

#: cinder/db/sqlalchemy/migrate_repo/versions/015_drop_migrations_table.py:62
#, python-format
msgid "Table |%s| not created"
msgstr ""

#: cinder/db/sqlalchemy/migrate_repo/versions/021_add_default_quota_class.py:76
msgid "Default quota class data not inserted into the DB."
msgstr ""

#: cinder/keymgr/barbican.py:76
#, python-format
msgid "Error creating Barbican client: %s"
msgstr ""

#: cinder/keymgr/barbican.py:113
#, python-format
msgid "Error creating key: %s"
msgstr ""

#: cinder/keymgr/barbican.py:168
#, python-format
msgid "Error storing key: %s"
msgstr ""

#: cinder/keymgr/barbican.py:196
#, python-format
msgid "Error copying key: %s"
msgstr ""

#: cinder/keymgr/barbican.py:233
#, python-format
msgid "Error getting secret data: %s"
msgstr ""

#: cinder/keymgr/barbican.py:252
#, python-format
msgid "Error getting secret metadata: %s"
msgstr ""

#: cinder/keymgr/barbican.py:281
#, python-format
msgid "Error getting key: %s"
msgstr ""

#: cinder/keymgr/barbican.py:298
#, python-format
msgid "Error deleting key: %s"
msgstr ""

#: cinder/openstack/common/loopingcall.py:95
#: cinder/tests/brick/test_brick_connector.py:494
msgid "in fixed duration looping call"
msgstr ""

#: cinder/openstack/common/loopingcall.py:138
msgid "in dynamic looping call"
msgstr ""

#: cinder/openstack/common/periodic_task.py:208
#, python-format
msgid "Error during %(full_task_name)s: %(e)s"
msgstr ""

#: cinder/openstack/common/policy.py:546 cinder/openstack/common/policy.py:826
#, python-format
msgid "Failed to understand rule %s"
msgstr ""

#: cinder/openstack/common/policy.py:556
#, python-format
msgid "No handler for matches of kind %s"
msgstr ""

#: cinder/openstack/common/service.py:269
msgid "Unhandled exception"
msgstr ""

#: cinder/scheduler/manager.py:108
#, python-format
msgid "Failed to create consistency group %(group_id)s."
msgstr ""

#: cinder/scheduler/manager.py:127
msgid "Failed to create scheduler manager volume flow"
msgstr ""

#: cinder/scheduler/scheduler_options.py:69
#, python-format
msgid "Could not stat scheduler options file %(filename)s: '%(e)s'"
msgstr ""

#: cinder/scheduler/scheduler_options.py:79
#, python-format
msgid "Could not decode scheduler options: '%s'"
msgstr ""

#: cinder/scheduler/filters/capacity_filter.py:44
msgid "Free capacity not set: volume node info collection broken."
msgstr ""

#: cinder/scheduler/flows/create_volume.py:103
#, python-format
msgid "Failed to run task %(name)s: %(cause)s"
msgstr ""

#: cinder/scheduler/flows/create_volume.py:120
#, python-format
msgid "Failed notifying on %(topic)s payload %(payload)s"
msgstr ""

#: cinder/tests/fake_driver.py:136
msgid "local_path not implemented"
msgstr ""

#: cinder/transfer/api.py:124
#, python-format
msgid "Failed to create transfer record for %s"
msgstr ""

#: cinder/transfer/api.py:188
#, python-format
msgid "Failed to update quota donating volume transfer id %s"
msgstr ""

#: cinder/volume/api.py:239
msgid "Failed to create api volume flow"
msgstr ""

#: cinder/volume/api.py:273
msgid "Failed to update quota for deleting volume"
msgstr ""

#: cinder/volume/api.py:782
#, python-format
msgid ""
"Unable to delete snapshot: %(snap_id)s, due to invalid status. Status "
"must be available or error, not %(snap_status)s."
msgstr ""

#: cinder/volume/api.py:792
#, python-format
msgid "Unable to delete snapshot: %s, because it is part of a consistency group."
msgstr ""

#: cinder/volume/api.py:1272
msgid "Unable to find service for given host."
msgstr ""

#: cinder/volume/driver.py:243 cinder/volume/drivers/hds/nfs.py:356
#: cinder/volume/drivers/netapp/dataontap/nfs_base.py:176
#, python-format
msgid "Recovering from a failed execute.  Try number %s"
msgstr ""

#: cinder/volume/driver.py:277 cinder/volume/manager.py:784
#, python-format
msgid "Error detaching volume %(volume)s, due to remove export failure."
msgstr ""

#: cinder/volume/driver.py:486 cinder/volume/manager.py:919
#, python-format
msgid ""
"Failed updating model of volume %(volume_id)s with driver provided model "
"%(model)s"
msgstr ""

#: cinder/volume/driver.py:932 cinder/volume/targets/iscsi.py:144
#, python-format
msgid "ISCSI discovery attempt failed for:%s"
msgstr ""

#: cinder/volume/driver.py:1084
#, python-format
msgid "The volume driver requires %(data)s in the connector."
msgstr ""

#: cinder/volume/driver.py:1367
#, python-format
msgid ""
"FibreChannelDriver validate_connector failed. No '%(setting)s'. Make sure"
" HBA state is Online."
msgstr ""

#: cinder/volume/manager.py:222
#, python-format
msgid "Failed to fetch pool name for volume: %s"
msgstr ""

#: cinder/volume/manager.py:282
#, python-format
msgid "Error encountered during initialization of driver: %(name)s"
msgstr ""

#: cinder/volume/manager.py:307
#, python-format
msgid "Failed to re-export volume %s: setting to error state"
msgstr ""

#: cinder/volume/manager.py:323
#, python-format
msgid ""
"Error encountered during re-exporting phase of driver initialization:  "
"%(name)s"
msgstr ""

#: cinder/volume/manager.py:380
msgid "Failed to create manager volume flow"
msgstr ""

#: cinder/volume/manager.py:474
#, python-format
msgid "Cannot delete volume %s: volume is busy"
msgstr ""

#: cinder/volume/manager.py:501
msgid "Failed to update usages deleting volume"
msgstr ""

#: cinder/volume/manager.py:572 cinder/volume/manager.py:1875
#, python-format
msgid ""
"Failed updating %(snapshot_id)s metadata using the provided volumes "
"%(volume_id)s metadata"
msgstr ""

#: cinder/volume/manager.py:617
#, python-format
msgid "Cannot delete snapshot %s: snapshot is busy"
msgstr ""

#: cinder/volume/manager.py:647 cinder/volume/manager.py:1975
msgid "Failed to update usages deleting snapshot"
msgstr ""

#: cinder/volume/manager.py:780
#, python-format
msgid "Error detaching volume %(volume)s, due to uninitialized driver."
msgstr ""

#: cinder/volume/manager.py:816
#, python-format
msgid "Error occurred while uploading volume %(volume_id)s to image %(image_id)s."
msgstr ""

#: cinder/volume/manager.py:1007
#, python-format
msgid ""
"Failed updating model of volume %(volume_id)s with drivers update "
"%(model)s during xfr."
msgstr ""

#: cinder/volume/manager.py:1348
#, python-format
msgid "volume %s: Error trying to extend volume"
msgstr ""

#: cinder/volume/manager.py:1426
msgid "Failed to update usages while retyping volume."
msgstr ""

#: cinder/volume/manager.py:1462
#, python-format
msgid ""
"Volume %s: driver error when trying to retype, falling back to generic "
"mechanism."
msgstr ""

#: cinder/volume/manager.py:1529
msgid "Failed to create manage_existing flow."
msgstr ""

#: cinder/volume/manager.py:1561
#, python-format
msgid "Failed to promote replica for volume %(id)s."
msgstr ""

#: cinder/volume/manager.py:1593
#, python-format
msgid "Failed to sync replica for volume %(id)s."
msgstr ""

#: cinder/volume/manager.py:1646
#, python-format
msgid "Error checking replication status for volume %s"
msgstr ""

#: cinder/volume/manager.py:1678
#, python-format
msgid "Consistency group %s: create failed"
msgstr ""

#: cinder/volume/manager.py:1770
msgid "Failed to update usages deleting consistency groups."
msgstr ""

#: cinder/volume/manager.py:1787
msgid "Failed to update usages deleting volume."
msgstr ""

#: cinder/volume/qos_specs.py:85 cinder/volume/qos_specs.py:106
#: cinder/volume/qos_specs.py:156 cinder/volume/qos_specs.py:198
#: cinder/volume/qos_specs.py:212 cinder/volume/qos_specs.py:226
#: cinder/volume/volume_types.py:55 cinder/volume/volume_types.py:71
#, python-format
msgid "DB error: %s"
msgstr ""

#: cinder/volume/volume_types.py:164
#, python-format
msgid ""
"Default volume type is not found,please check default_volume_type config:"
" %s"
msgstr ""

#: cinder/volume/drivers/datera.py:181
msgid "Failed to get updated stats from Datera Cluster."
msgstr ""

#: cinder/volume/drivers/eqlx.py:236
#, python-format
msgid "Error running SSH command: \"%s\"."
msgstr ""

#: cinder/volume/drivers/eqlx.py:354
msgid "Failed to setup the Dell EqualLogic driver."
msgstr ""

#: cinder/volume/drivers/eqlx.py:371
#, python-format
msgid "Failed to create volume \"%s\"."
msgstr ""

#: cinder/volume/drivers/eqlx.py:381
#, python-format
msgid "Failed to add multihost-access for volume \"%s\"."
msgstr ""

#: cinder/volume/drivers/eqlx.py:396
#, python-format
msgid "Failed to delete volume \"%s\"."
msgstr ""

#: cinder/volume/drivers/eqlx.py:412
#, python-format
msgid "Failed to create snapshot of volume \"%s\"."
msgstr ""

#: cinder/volume/drivers/eqlx.py:426
#, python-format
msgid "Failed to create volume from snapshot \"%s\"."
msgstr ""

#: cinder/volume/drivers/eqlx.py:439
#, python-format
msgid "Failed to create clone of volume \"%s\"."
msgstr ""

#: cinder/volume/drivers/eqlx.py:449
#, python-format
msgid "Failed to delete snapshot %(snap)s of volume %(vol)s."
msgstr ""

#: cinder/volume/drivers/eqlx.py:470
#, python-format
msgid "Failed to initialize connection to volume \"%s\"."
msgstr ""

#: cinder/volume/drivers/eqlx.py:485
#, python-format
msgid "Failed to terminate connection to volume \"%s\"."
msgstr ""

#: cinder/volume/drivers/eqlx.py:511
#, python-format
msgid "Failed to ensure export of volume \"%s\"."
msgstr ""

#: cinder/volume/drivers/eqlx.py:530
#, python-format
msgid ""
"Failed to extend_volume %(name)s from %(current_size)sGB to "
"%(new_size)sGB."
msgstr ""

#: cinder/volume/drivers/glusterfs.py:164
#, python-format
msgid "Exception during unmounting %s"
msgstr ""

#: cinder/volume/drivers/glusterfs.py:175
#, python-format
msgid "Failed to umount %(share)s, reason=%(stderr)s"
msgstr ""

#: cinder/volume/drivers/glusterfs.py:440 cinder/volume/drivers/remotefs.py:201
#, python-format
msgid "Exception during mounting %s"
msgstr ""

#: cinder/volume/drivers/lvm.py:128
#, python-format
msgid "Volume device file path %s does not exist."
msgstr ""

#: cinder/volume/drivers/lvm.py:135
#, python-format
msgid "Size for volume: %s not found, cannot secure delete."
msgstr ""

#: cinder/volume/drivers/lvm.py:311
#, python-format
msgid "Unabled to delete due to existing snapshot for volume: %s"
msgstr ""

#: cinder/volume/drivers/lvm.py:516
#, python-format
msgid "Destination Volume Group %s does not exist"
msgstr ""

#: cinder/volume/drivers/nfs.py:166
#, python-format
msgid "Mount failure for %(share)s after %(count)d attempts."
msgstr ""

#: cinder/volume/drivers/nimble.py:140
msgid ""
"Failed to create SOAP client.Check san_ip, username, password and make "
"sure the array version is compatible"
msgstr ""

#: cinder/volume/drivers/nimble.py:396
#, python-format
msgid "Re-throwing Exception %s"
msgstr ""

#: cinder/volume/drivers/pure.py:230
#, python-format
msgid "Snapshot deletion failed with message: %s"
msgstr ""

#: cinder/volume/drivers/pure.py:345
#, python-format
msgid "Unable to find host object in Purity with IQN: %(iqn)s."
msgstr ""

#: cinder/volume/drivers/pure.py:358
#, python-format
msgid "Disconnection failed with message: %(msg)s."
msgstr ""

#: cinder/volume/drivers/quobyte.py:424
#, python-format
msgid "The mount %(mount_path)s is not a valid Quobyte USP volume. Error: %(exc)s"
msgstr ""

#: cinder/volume/drivers/rbd.py:218
#, python-format
msgid "error opening rbd image %s"
msgstr ""

#: cinder/volume/drivers/rbd.py:312
msgid "error connecting to ceph cluster."
msgstr ""

#: cinder/volume/drivers/rbd.py:372 cinder/volume/drivers/sheepdog.py:171
msgid "error refreshing volume stats"
msgstr ""

#: cinder/volume/drivers/rbd.py:721
msgid "Retype with host migration not supported"
msgstr ""

#: cinder/volume/drivers/rbd.py:725
msgid "Retype of encryption type not supported"
msgstr ""

#: cinder/volume/drivers/rbd.py:729
msgid "Retype of extra_specs not supported"
msgstr ""

#: cinder/volume/drivers/remotefs.py:383
#, python-format
msgid "Share %s ignored due to invalid format. Must be of form address:/export."
msgstr ""

#: cinder/volume/drivers/remotefs.py:531
#, python-format
msgid "Failed to created Cinder secure environment indicator file: %s"
msgstr ""

#: cinder/volume/drivers/remotefs.py:1200
msgid "Call to Nova to create snapshot failed"
msgstr ""

#: cinder/volume/drivers/remotefs.py:1287
msgid "Call to Nova delete snapshot failed"
msgstr ""

#: cinder/volume/drivers/solidfire.py:311
#, python-format
msgid "Failed to retrieve volume SolidFire-ID: %s in get_by_account!"
msgstr ""

#: cinder/volume/drivers/solidfire.py:493
#, python-format
msgid "Volume %s, not found on SF Cluster."
msgstr ""

#: cinder/volume/drivers/solidfire.py:496
#, python-format
msgid "Found %(count)s volumes mapped to id: %(uuid)s."
msgstr ""

#: cinder/volume/drivers/solidfire.py:556
#, python-format
msgid "Failed image conversion during cache creation: %s"
msgstr ""

#: cinder/volume/drivers/solidfire.py:732
#, python-format
msgid ""
"Account for Volume ID %s was not found on the SolidFire Cluster while "
"attempting delete_volume operation!"
msgstr ""

#: cinder/volume/drivers/solidfire.py:735
msgid "This usually means the volume was never successfully created."
msgstr ""

#: cinder/volume/drivers/solidfire.py:751
#, python-format
msgid ""
"Volume ID %s was not found on the SolidFire Cluster while attempting "
"delete_volume operation!"
msgstr ""

#: cinder/volume/drivers/solidfire.py:826
#, python-format
msgid ""
"Volume ID %s was not found on the SolidFire Cluster while attempting "
"extend_volume operation!"
msgstr ""

#: cinder/volume/drivers/solidfire.py:854
msgid "Failed to get updated stats"
msgstr ""

#: cinder/volume/drivers/solidfire.py:891
#, python-format
msgid ""
"Volume ID %s was not found on the SolidFire Cluster while attempting "
"attach_volume operation!"
msgstr ""

#: cinder/volume/drivers/solidfire.py:917
#, python-format
msgid ""
"Volume ID %s was not found on the SolidFire Cluster while attempting "
"detach_volume operation!"
msgstr ""

#: cinder/volume/drivers/solidfire.py:942
#, python-format
msgid ""
"Volume ID %s was not found on the SolidFire Cluster while attempting "
"accept_transfer operation!"
msgstr ""

#: cinder/volume/drivers/solidfire.py:1088
#, python-format
msgid ""
"Account for Volume ID %s was not found on the SolidFire Cluster while "
"attempting unmanage operation!"
msgstr ""

#: cinder/volume/drivers/srb.py:123
msgid "Error activating Volume Group"
msgstr ""

#: cinder/volume/drivers/srb.py:143
msgid "Error deactivating Volume Group"
msgstr ""

#: cinder/volume/drivers/srb.py:161
msgid "Error destroying Volume Group"
msgstr ""

#: cinder/volume/drivers/srb.py:179
msgid "Error resizing Physical Volume"
msgstr ""

#: cinder/volume/drivers/srb.py:205
msgid "Error extending thin provisioning pool"
msgstr ""

#: cinder/volume/drivers/srb.py:339
msgid "Cound not setup urls on the Block Driver."
msgstr ""

#: cinder/volume/drivers/srb.py:635
#, python-format
msgid "Could not deactivate volume groupe %s"
msgstr ""

#: cinder/volume/drivers/srb.py:643
#, python-format
msgid "Could not detach volume %(vol)s from device %(dev)s."
msgstr ""

#: cinder/volume/drivers/srb.py:661
#, python-format
msgid "Unable to delete due to existing snapshot for volume: %s."
msgstr ""

#: cinder/volume/drivers/storpool.py:154
msgid "Could not delete the temp snapshot {n}: {msg}"
msgstr ""

#: cinder/volume/drivers/storpool.py:196
msgid "StorPoolDriver API initialization failed: {e}"
msgstr ""

#: cinder/volume/drivers/storpool.py:290 cinder/volume/drivers/storpool.py:318
msgid "Could not remove the temp snapshot {n} for {v}: {e}"
msgstr ""

#: cinder/volume/drivers/xio.py:91
msgid "san ip must be configured!"
msgstr ""

#: cinder/volume/drivers/xio.py:96
msgid "san_login must be configured!"
msgstr ""

#: cinder/volume/drivers/xio.py:101
msgid "san_password must be configured!"
msgstr ""

#: cinder/volume/drivers/xio.py:119
#, python-format
msgid "Array query failed - No response (%d)!"
msgstr ""

#: cinder/volume/drivers/xio.py:135
msgid "Array query failed. No capabilities in response!"
msgstr ""

#: cinder/volume/drivers/xio.py:154
msgid "ISE FW version is not compatible with Openstack!"
msgstr ""

#: cinder/volume/drivers/xio.py:162
msgid "Array query failed. No global id in XML response!"
msgstr ""

#: cinder/volume/drivers/xio.py:168
msgid "Array query failed. No controllers in response!"
msgstr ""

#: cinder/volume/drivers/xio.py:208
msgid "ISE globalid not set!"
msgstr ""

#: cinder/volume/drivers/xio.py:220
msgid "Primary IP must be set!"
msgstr ""

#: cinder/volume/drivers/xio.py:415
#, python-format
msgid "Connection to %s failed and no secondary!"
msgstr ""

#: cinder/volume/drivers/xio.py:427
#, python-format
msgid "Could not connect to %(primary)s or %(secondary)s!"
msgstr ""

#: cinder/volume/drivers/xio.py:502 cinder/volume/drivers/xio.py:542
#, python-format
msgid "Controller GET failed (%d)"
msgstr ""

#: cinder/volume/drivers/xio.py:528
msgid "Failed to get IQN!"
msgstr ""

#: cinder/volume/drivers/xio.py:570
#, python-format
msgid "Failed to get allocation information (%d)!"
msgstr ""

#: cinder/volume/drivers/xio.py:581
msgid "Failed to get LUN information!"
msgstr ""

#: cinder/volume/drivers/xio.py:643
#, python-format
msgid "Could not GET allocation information (%d)!"
msgstr ""

#: cinder/volume/drivers/xio.py:711
#, python-format
msgid "Failed to present volume %(name)s (%(status)d)!"
msgstr ""

#: cinder/volume/drivers/xio.py:737
#, python-format
msgid "Failed to get allocation information: %(host)s (%(status)d)!"
msgstr ""

#: cinder/volume/drivers/xio.py:772
#, python-format
msgid "Could not find any hosts (%s)"
msgstr ""

#: cinder/volume/drivers/xio.py:830
#, python-format
msgid "POST for host create failed (%s)!"
msgstr ""

#: cinder/volume/drivers/xio.py:858
#, python-format
msgid "Source volume %s not ready!"
msgstr ""

#: cinder/volume/drivers/xio.py:884
#, python-format
msgid "Prepare clone failed for %s."
msgstr ""

#: cinder/volume/drivers/xio.py:897
#, python-format
msgid "Clone %s not in prepared state!"
msgstr ""

#: cinder/volume/drivers/xio.py:904
#, python-format
msgid "Commit clone failed: %(name)s (%(status)d)!"
msgstr ""

#: cinder/volume/drivers/xio.py:919
#, python-format
msgid "Commit failed for %s!"
msgstr ""

#: cinder/volume/drivers/xio.py:1174
#, python-format
msgid "Failed to create volume: %(name)s (%(status)s)"
msgstr ""

#: cinder/volume/drivers/xio.py:1191
#, python-format
msgid "Failed to create volume %s."
msgstr ""

#: cinder/volume/drivers/xio.py:1256
#, python-format
msgid "modify volume: %s does not exist!"
msgstr ""

#: cinder/volume/drivers/xio.py:1266
#, python-format
msgid "Modify volume PUT failed: %(name)s (%(status)d)."
msgstr ""

#: cinder/volume/drivers/xio.py:1297
msgid "manage_existing: No source-name in ref!"
msgstr ""

#: cinder/volume/drivers/xio.py:1318
msgid "manage_existing_get_size: No source-name in ref!"
msgstr ""

#: cinder/volume/drivers/xio.py:1325
#, python-format
msgid "manage_existing_get_size: %s does not exist!"
msgstr ""

#: cinder/volume/drivers/xio.py:1336
#, python-format
msgid "unmanage: Volume %s does not exist!"
msgstr ""

#: cinder/volume/drivers/xio.py:1355
msgid "Host could not be found!"
msgstr ""

#: cinder/volume/drivers/xio.py:1364
#, python-format
msgid "Host PUT failed (%s)."
msgstr ""

#: cinder/volume/drivers/xio.py:1415
msgid "iscsi_ip_address must be set!"
msgstr ""

#: cinder/volume/drivers/cloudbyte/cloudbyte.py:299
#, python-format
msgid ""
"Error in creating volume [%(vol)s] in CloudByte storage. Exhausted all "
"[%(max)s] attempts."
msgstr ""

#: cinder/volume/drivers/cloudbyte/cloudbyte.py:579
#, python-format
msgid "TSM [%s] not found in CloudByte storage."
msgstr ""

#: cinder/volume/drivers/cloudbyte/cloudbyte.py:706
#, python-format
msgid "CloudByte does not have a volume corresponding to OpenStack volume [%s]."
msgstr ""

#: cinder/volume/drivers/cloudbyte/cloudbyte.py:710
#, python-format
msgid "CloudByte volume information not available for OpenStack volume [%s]."
msgstr ""

#: cinder/volume/drivers/cloudbyte/cloudbyte.py:893
#, python-format
msgid "CloudByte snapshot information is not available for OpenStack volume [%s]."
msgstr ""

#: cinder/volume/drivers/dell/dell_storagecenter_api.py:173
#, python-format
msgid "Invalid return blob: %s"
msgstr ""

#: cinder/volume/drivers/dell/dell_storagecenter_api.py:186
#, python-format
msgid "Error invalid json: %s"
msgstr ""

#: cinder/volume/drivers/dell/dell_storagecenter_api.py:195
#, python-format
msgid "Invalid API object: %s"
msgstr ""

#: cinder/volume/drivers/dell/dell_storagecenter_api.py:204
#, python-format
msgid "Login error: %(c)d %(r)s"
msgstr ""

#: cinder/volume/drivers/dell/dell_storagecenter_api.py:228
#, python-format
msgid "Failed to find %(s)s.  Result %(r)s"
msgstr ""

#: cinder/volume/drivers/dell/dell_storagecenter_api.py:287
#, python-format
msgid "Unable to create folder path %s"
msgstr ""

#: cinder/volume/drivers/dell/dell_storagecenter_api.py:378
#, python-format
msgid "Unable to create folder %s"
msgstr ""

#: cinder/volume/drivers/dell/dell_storagecenter_api.py:394
#, python-format
msgid "ScVolume create error %(name)s: %(c)d %(r)s"
msgstr ""

#: cinder/volume/drivers/dell/dell_storagecenter_api.py:473
#, python-format
msgid "AddHba error: %(i)s to %(s)s : %(c)d %(r)s"
msgstr ""

#: cinder/volume/drivers/dell/dell_storagecenter_api.py:557
#, python-format
msgid "ScPhysicalServer create error: %(i)s: %(c)d %(r)s"
msgstr ""

#: cinder/volume/drivers/dell/dell_storagecenter_api.py:570
msgid "Error adding HBA to server"
msgstr ""

#: cinder/volume/drivers/dell/dell_storagecenter_api.py:606
#, python-format
msgid "ScServer error: %(c)d %(r)s"
msgstr ""

#: cinder/volume/drivers/dell/dell_storagecenter_api.py:634
msgid "Error getting FaultDomainList"
msgstr ""

#: cinder/volume/drivers/dell/dell_storagecenter_api.py:656
msgid "Unable to find FC intitiators"
msgstr ""

#: cinder/volume/drivers/dell/dell_storagecenter_api.py:683
#, python-format
msgid "Unable to find volume mappings: %s"
msgstr ""

#: cinder/volume/drivers/dell/dell_storagecenter_api.py:686
msgid "_find_mappings: volume is not active"
msgstr ""

#: cinder/volume/drivers/dell/dell_storagecenter_api.py:703
#, python-format
msgid "Unable to find controller port: %s"
msgstr ""

#: cinder/volume/drivers/dell/dell_storagecenter_api.py:744
msgid "Find_wwns: Volume appears unmapped"
msgstr ""

#: cinder/volume/drivers/dell/dell_storagecenter_api.py:778
msgid "Find_iqn: Volume appears unmapped"
msgstr ""

#: cinder/volume/drivers/dell/dell_storagecenter_api.py:810
#, python-format
msgid "Unable to map %(vol)s to %(srv)s"
msgstr ""

#: cinder/volume/drivers/dell/dell_storagecenter_api.py:839
#, python-format
msgid "Unable to unmap Volume %s"
msgstr ""

#: cinder/volume/drivers/dell/dell_storagecenter_api.py:895
msgid "Error creating replay."
msgstr ""

#: cinder/volume/drivers/dell/dell_storagecenter_api.py:926
#, python-format
msgid "Invalid ReplayList return: %s"
msgstr ""

#: cinder/volume/drivers/dell/dell_storagecenter_api.py:992
#, python-format
msgid "Unable to create volume %s from replay"
msgstr ""

#: cinder/volume/drivers/dell/dell_storagecenter_api.py:1012
msgid "Error: unable to snap replay"
msgstr ""

#: cinder/volume/drivers/dell/dell_storagecenter_api.py:1025
#, python-format
msgid "Error expanding volume %(n)s: %(c)d %(r)s"
msgstr ""

#: cinder/volume/drivers/dell/dell_storagecenter_common.py:110
#: cinder/volume/drivers/dell/dell_storagecenter_common.py:193
#: cinder/volume/drivers/dell/dell_storagecenter_common.py:223
#, python-format
msgid "Failed to create volume %s"
msgstr ""

#: cinder/volume/drivers/dell/dell_storagecenter_common.py:129
#, python-format
msgid "Failed to delete volume %s"
msgstr ""

#: cinder/volume/drivers/dell/dell_storagecenter_common.py:279
#, python-format
msgid "Failed to ensure export of volume %s"
msgstr ""

#: cinder/volume/drivers/dell/dell_storagecenter_fc.py:101
msgid "Lun mapping returned null!"
msgstr ""

#: cinder/volume/drivers/dell/dell_storagecenter_fc.py:105
msgid "Failed to initialize connection "
msgstr ""

#: cinder/volume/drivers/dell/dell_storagecenter_fc.py:154
msgid "Failed to terminate connection"
msgstr ""

#: cinder/volume/drivers/dell/dell_storagecenter_iscsi.py:83
msgid "Volume mapped to invalid path."
msgstr ""

#: cinder/volume/drivers/dell/dell_storagecenter_iscsi.py:101
#, python-format
msgid "Failed to initialize connection  %(i)s %(n)s"
msgstr ""

#: cinder/volume/drivers/dell/dell_storagecenter_iscsi.py:135
#, python-format
msgid "Failed to terminate connection %(i)s %(n)s"
msgstr ""

#: cinder/volume/drivers/emc/emc_vmax_common.py:327
#, python-format
msgid "Error Attaching volume %(vol)s."
msgstr ""

#: cinder/volume/drivers/emc/emc_vmax_common.py:537
#, python-format
msgid "PoolName %(poolName)s must be in the file %(emcConfigFileName)s "
msgstr ""

#: cinder/volume/drivers/emc/emc_vmax_common.py:544
#, python-format
msgid ""
"Array Serial Number %(arrayName)s must be in the file "
"%(emcConfigFileName)s "
msgstr ""

#: cinder/volume/drivers/emc/emc_vmax_common.py:649
#, python-format
msgid "Volume %(name)s not found on the array. No volume to migrate using retype."
msgstr ""

#: cinder/volume/drivers/emc/emc_vmax_common.py:661
#, python-format
msgid ""
"Volume %(name)s is not suitable for storage assisted migration using "
"retype"
msgstr ""

#: cinder/volume/drivers/emc/emc_vmax_common.py:948
#: cinder/volume/drivers/emc/emc_vmax_common.py:1006
#: cinder/volume/drivers/emc/emc_vmax_common.py:1382
#: cinder/volume/drivers/emc/emc_vmax_common.py:1695
#: cinder/volume/drivers/emc/emc_vmax_common.py:2148
#: cinder/volume/drivers/emc/emc_vmax_fast.py:520
#: cinder/volume/drivers/emc/emc_vmax_fast.py:662
#: cinder/volume/drivers/emc/emc_vmax_masking.py:210
#: cinder/volume/drivers/emc/emc_vmax_masking.py:884
#: cinder/volume/drivers/emc/emc_vmax_provision.py:494
#: cinder/volume/drivers/emc/emc_vmax_provision.py:505
#: cinder/volume/drivers/emc/emc_vmax_provision.py:513
#: cinder/volume/drivers/emc/emc_vmax_utils.py:308
#: cinder/volume/drivers/emc/emc_vmax_utils.py:369
#: cinder/volume/drivers/emc/emc_vmax_utils.py:1269
#: cinder/volume/drivers/fujitsu/eternus_dx_common.py:1428
#: cinder/volume/drivers/fujitsu/eternus_dx_common.py:1492
#: cinder/zonemanager/drivers/cisco/cisco_fc_zone_driver.py:220
#, python-format
msgid "Exception: %s"
msgstr ""

#: cinder/volume/drivers/emc/emc_vmax_common.py:1047
#, python-format
msgid ""
"Failed to add %(volumeName)s to default storage group for fast policy "
"%(fastPolicyName)s "
msgstr ""

#: cinder/volume/drivers/emc/emc_vmax_common.py:1072
msgid "Error getting target pool name and array"
msgstr ""

#: cinder/volume/drivers/emc/emc_vmax_common.py:1084
msgid "Error parsing target pool name, array, and fast policy"
msgstr ""

#: cinder/volume/drivers/emc/emc_vmax_common.py:1088
#, python-format
msgid ""
"The source array : %(sourceArraySerialNumber)s does not match the target "
"array: %(targetArraySerialNumber)sskipping storage-assisted migration"
msgstr ""

#: cinder/volume/drivers/emc/emc_vmax_common.py:1104
#, python-format
msgid ""
"No action required. Volume : %(volumeName)s is already part of pool : "
"%(pool)s"
msgstr ""

#: cinder/volume/drivers/emc/emc_vmax_common.py:1114
msgid "Only available volumes can be migrated between different protocols"
msgstr ""

#: cinder/volume/drivers/emc/emc_vmax_common.py:1401
#, python-format
msgid "Target end points do not exist for hardware Id : %(hardwareIdInstance)s "
msgstr ""

#: cinder/volume/drivers/emc/emc_vmax_common.py:2077
#: cinder/volume/drivers/fujitsu/eternus_dx_common.py:519
#, python-format
msgid "Volume %(name)s not found on the array. No volume to delete."
msgstr ""

#: cinder/volume/drivers/emc/emc_vmax_common.py:2139
#, python-format
msgid ""
"Failed to Roll back to re-add volume %(volumeName)s to default storage "
"group for fast policy %(fastPolicyName)s: Please contact your sysadmin to"
" get the volume returned to the default storage group"
msgstr ""

#: cinder/volume/drivers/emc/emc_vmax_fast.py:500
#, python-format
msgid "Cannot find the fast policy %(fastPolicyName)s"
msgstr ""

#: cinder/volume/drivers/emc/emc_vmax_fast.py:521
#, python-format
msgid ""
"Failed to add storage group %(storageGroupInstanceName)s  to tier policy "
"rule %(tierPolicyRuleInstanceName)s"
msgstr ""

#: cinder/volume/drivers/emc/emc_vmax_fast.py:587
#, python-format
msgid "Error disassociating storage group from policy: %s"
msgstr ""

#: cinder/volume/drivers/emc/emc_vmax_masking.py:293
#, python-format
msgid "Looks like masking view: %(maskingViewName)s has recently been deleted."
msgstr ""

#: cinder/volume/drivers/emc/emc_vmax_masking.py:334
#, python-format
msgid "Cannot get storage Group from job : %(storageGroupName)s. "
msgstr ""

#: cinder/volume/drivers/emc/emc_vmax_masking.py:351
#, python-format
msgid ""
"Cannot add and verify tier policy association for storage group : "
"%(storageGroupName)s to FAST policy : %(fastPolicyName)s. "
msgstr ""

#: cinder/volume/drivers/emc/emc_vmax_masking.py:385
#, python-format
msgid ""
"Could not find port group : %(portGroupName)s. Check that the EMC "
"configuration file has the correct port group name. "
msgstr ""

#: cinder/volume/drivers/emc/emc_vmax_masking.py:429
#: cinder/volume/drivers/emc/emc_vmax_masking.py:976
#, python-format
msgid ""
"Initiator Name(s) %(initiatorNames)s are not on array "
"%(storageSystemName)s "
msgstr ""

#: cinder/volume/drivers/emc/emc_vmax_masking.py:1009
#, python-format
msgid ""
"One of the components of the original masking view %(maskingViewName)s "
"cannot be retrieved so please contact your system administrator to check "
"that the correct initiator(s) are part of masking "
msgstr ""

#: cinder/volume/drivers/emc/emc_vmax_utils.py:296
#, python-format
msgid "_wait_for_job_complete failed after %(retries)d tries."
msgstr ""

#: cinder/volume/drivers/emc/emc_vmax_utils.py:359
#, python-format
msgid "_wait_for_sync failed after %(retries)d tries."
msgstr ""

#: cinder/volume/drivers/emc/emc_vnx_cli.py:213
msgid "san_secondary_ip is configured as the same value as san_ip."
msgstr ""

#: cinder/volume/drivers/emc/emc_vnx_cli.py:313
#, python-format
msgid "Error on enable compression on lun %s."
msgstr ""

#: cinder/volume/drivers/emc/emc_vnx_cli.py:324
#, python-format
msgid "Error on adding lun to consistency group. %s"
msgstr ""

#: cinder/volume/drivers/emc/emc_vnx_cli.py:1005
#, python-format
msgid "Invalid value for %(key)s, value is %(value)s."
msgstr ""

#: cinder/volume/drivers/emc/emc_vnx_cli.py:1048
#, python-format
msgid "Error happened during storage pool querying, %s."
msgstr ""

#: cinder/volume/drivers/emc/emc_vnx_cli.py:1539
msgid "The given extra_spec or valid_values is None."
msgstr ""

#: cinder/volume/drivers/emc/emc_vnx_cli.py:2371
#, python-format
msgid "Failed to find an available iSCSI targets for %s."
msgstr ""

#: cinder/volume/drivers/emc/emc_vnx_cli.py:2589
msgid "Error parsing output for FastCache Command."
msgstr ""

#: cinder/volume/drivers/emc/xtremio.py:93
msgid "can't create 2 volumes with the same name"
msgstr ""

#: cinder/volume/drivers/emc/xtremio.py:96
#, python-format
msgid "Bad response from XMS, %s"
msgstr ""

#: cinder/volume/drivers/emc/xtremio.py:100
#, python-format
msgid "bad API response, %s"
msgstr ""

#: cinder/volume/drivers/emc/xtremio.py:128
#, python-format
msgid "querying %(typ)s, %(req)s failed to parse result, return value = %(res)s"
msgstr ""

#: cinder/volume/drivers/emc/xtremio.py:285
#, python-format
msgid "Can't find volume to map %s"
msgstr ""

#: cinder/volume/drivers/fujitsu/eternus_dx_common.py:247
#, python-format
msgid ""
"Error Create Volume: %(volumename)s.  Return code: %(rc)lu.  Error: "
"%(error)s"
msgstr ""

#: cinder/volume/drivers/fujitsu/eternus_dx_common.py:596
#, python-format
msgid "Cannot find Replication Service to create snapshot for volume %s."
msgstr ""

#: cinder/volume/drivers/fujitsu/eternus_dx_common.py:719
#, python-format
msgid ""
"Snapshot: %(snapshot)s: volume: %(volume)s not found on the array. No "
"snapshot to delete."
msgstr ""

#: cinder/volume/drivers/fujitsu/eternus_dx_common.py:1419
#, python-format
msgid "_wait_for_job_complete failed after %(retries)d tries"
msgstr ""

#: cinder/volume/drivers/fujitsu/eternus_dx_common.py:1483
#, python-format
msgid "_wait_for_sync failed after %(retries)d tries"
msgstr ""

#: cinder/volume/drivers/hds/hds.py:106 cinder/volume/drivers/hds/iscsi.py:82
#: cinder/volume/drivers/hds/nfs.py:71
#, python-format
msgid "XML exception reading parameter: %s"
msgstr ""

#: cinder/volume/drivers/hds/hds.py:200 cinder/volume/drivers/hds/iscsi.py:268
#: cinder/volume/drivers/hds/nfs.py:195
#, python-format
msgid "No configuration found for service: %s"
msgstr ""

#: cinder/volume/drivers/hds/hds.py:253 cinder/volume/drivers/hds/iscsi.py:346
#, python-format
msgid "HDP not found: %s"
msgstr ""

#: cinder/volume/drivers/hds/hds.py:292 cinder/volume/drivers/hds/iscsi.py:393
#, python-format
msgid "iSCSI portal not found for service: %s"
msgstr ""

#: cinder/volume/drivers/hds/iscsi.py:92 cinder/volume/drivers/hds/nfs.py:84
#, python-format
msgid "Can't open config file: %s"
msgstr ""

#: cinder/volume/drivers/hds/iscsi.py:98 cinder/volume/drivers/hds/nfs.py:90
#, python-format
msgid "Error parsing config file: %s"
msgstr ""

#: cinder/volume/drivers/hds/iscsi.py:244
msgid "CHAP authentication disabled"
msgstr ""

#: cinder/volume/drivers/hds/iscsi.py:505
msgid "delete_vol: provider location empty."
msgstr ""

#: cinder/volume/drivers/hds/iscsi.py:676
#, python-format
msgid "Array mismatch %(myid)s vs %(arid)s"
msgstr ""

#: cinder/volume/drivers/hds/nfs.py:467
#, python-format
msgid "NFS share %(share)s has no service entry: %(svc)s -> %(hdp)s"
msgstr ""

#: cinder/volume/drivers/hitachi/hbsd_common.py:721
#, python-format
msgid "Failed to update volume status: %s"
msgstr ""

#: cinder/volume/drivers/hitachi/hbsd_horcm.py:217
msgid "Failed to shutdown horcm."
msgstr ""

#: cinder/volume/drivers/hitachi/hbsd_horcm.py:278
msgid "horcm command timeout."
msgstr ""

#: cinder/volume/drivers/hitachi/hbsd_horcm.py:285
msgid "Failed to authenticate user."
msgstr ""

#: cinder/volume/drivers/hitachi/hbsd_horcm.py:294
msgid "Failed to start horcm."
msgstr ""

#: cinder/volume/drivers/hitachi/hbsd_horcm.py:298
msgid "Unexpected error occurs in horcm."
msgstr ""

#: cinder/volume/drivers/hitachi/hbsd_iscsi.py:189
#, python-format
msgid "Failed to add target(port: %s)"
msgstr ""

#: cinder/volume/drivers/hitachi/hbsd_snm2.py:75
msgid "snm2 command timeout."
msgstr ""

#: cinder/volume/drivers/hitachi/hbsd_snm2.py:89
msgid "Unexpected error occurs in snm2."
msgstr ""

#: cinder/volume/drivers/huawei/huawei_t.py:438
msgid "validate_connector: The FC driver requires the wwpns in the connector."
msgstr ""

#: cinder/volume/drivers/huawei/huawei_utils.py:41
#, python-format
msgid "parse_xml_file: %s"
msgstr ""

#: cinder/volume/drivers/huawei/rest_common.py:86
#, python-format
msgid ""
"\n"
"Bad response from server: %s."
msgstr ""

#: cinder/volume/drivers/huawei/rest_common.py:92
#, python-format
msgid "JSON transfer error: %s."
msgstr ""

#: cinder/volume/drivers/huawei/rest_common.py:279
#, python-format
msgid "_read_xml: %s"
msgstr ""

#: cinder/volume/drivers/huawei/rest_common.py:689
msgid ""
"Error occurred when adding hostgroup and lungroup to view. Remove lun "
"from lungroup now."
msgstr ""

#: cinder/volume/drivers/huawei/rest_common.py:924
#, python-format
msgid "JSON transfer data error. %s"
msgstr ""

#: cinder/volume/drivers/huawei/ssh_common.py:503
#, python-format
msgid "_execute_cli: %s"
msgstr ""

#: cinder/volume/drivers/huawei/ssh_common.py:935
#, python-format
msgid "map_volume: Volume %s was not found."
msgstr ""

#: cinder/volume/drivers/huawei/ssh_common.py:1104
#, python-format
msgid "remove_map: Host %s does not exist."
msgstr ""

#: cinder/volume/drivers/huawei/ssh_common.py:1109
#, python-format
msgid "remove_map: Volume %s does not exist."
msgstr ""

#: cinder/volume/drivers/huawei/ssh_common.py:1314
msgid ""
"_get_device_type: The driver only supports Dorado5100 and Dorado 2100 G2 "
"now."
msgstr ""

#: cinder/volume/drivers/huaweistorhyper/huaweistorac.py:129
#, python-format
msgid "Source volume %(name)s does not exist."
msgstr ""

#: cinder/volume/drivers/huaweistorhyper/huaweistorac.py:172
#, python-format
msgid "Error from get volume stats: %s, using default stats."
msgstr ""

#: cinder/volume/drivers/huaweistorhyper/huaweistorac.py:211
#, python-format
msgid "Delete snapshot failed: %s."
msgstr ""

#: cinder/volume/drivers/huaweistorhyper/huaweistorac.py:244
#, python-format
msgid "Copy volume to image failed: %s."
msgstr ""

#: cinder/volume/drivers/huaweistorhyper/huaweistorac.py:266
#, python-format
msgid "Copy volume data failed: %s."
msgstr ""

#: cinder/volume/drivers/huaweistorhyper/huaweistorac.py:289
#, python-format
msgid "Delete temp volume failed after %(method)s: %(ex)s."
msgstr ""

#: cinder/volume/drivers/huaweistorhyper/huaweistorac.py:296
#, python-format
msgid "Delete temp snapshot failed after %(method)s: %(ex)s."
msgstr ""

#: cinder/volume/drivers/huaweistorhyper/huaweistorac.py:377
#, python-format
msgid "Error from get block storage capacity: %s."
msgstr ""

#: cinder/volume/drivers/huaweistorhyper/huaweistorac.py:422
#, python-format
msgid "Delete volume failed,volume_name: %s."
msgstr ""

#: cinder/volume/drivers/huaweistorhyper/huaweistorac.py:440
#, python-format
msgid "Delete snapshot failed,snapshot_name: %s."
msgstr ""

#: cinder/volume/drivers/huaweistorhyper/huaweistorac.py:452
#, python-format
msgid "Check volume_name delete finished failed: %s."
msgstr ""

#: cinder/volume/drivers/huaweistorhyper/huaweistorac.py:463
#, python-format
msgid "Check snapshot delete finished failed: %s."
msgstr ""

#: cinder/volume/drivers/huaweistorhyper/huaweistorac.py:555
msgid "Get pool id failed, invalid pool id."
msgstr ""

#: cinder/volume/drivers/huaweistorhyper/huaweistorac.py:749
msgid "Invalid info type."
msgstr ""

#: cinder/volume/drivers/huaweistorhyper/utils.py:68
#, python-format
msgid "Parse_xml_file: %s."
msgstr ""

#: cinder/volume/drivers/huaweistorhyper/vbs_client.py:47
msgid "No valid ip in vbs ip list."
msgstr ""

#: cinder/volume/drivers/ibm/flashsystem.py:238
#, python-format
msgid "_copy_vdisk_data: Failed to copy %(src)s to %(dest)s."
msgstr ""

#: cinder/volume/drivers/ibm/flashsystem.py:759
#, python-format
msgid ""
"%(fun)s: Failed with unexpected CLI output.\n"
" Command: %(cmd)s\n"
"stdout: %(out)s\n"
"stderr: %(err)s\n"
msgstr ""

#: cinder/volume/drivers/ibm/flashsystem.py:918
#, python-format
msgid ""
"_unmap_vdisk_from_host: No mapping of volume %(vol_name)s to host "
"%(host_name)s found."
msgstr ""

#: cinder/volume/drivers/ibm/flashsystem.py:1141
msgid "The connector does not contain the required information: wwpns is missing"
msgstr ""

#: cinder/volume/drivers/ibm/flashsystem.py:1216
#, python-format
msgid ""
"initialize_connection: Failed to collect return properties for volume "
"%(vol)s and connector %(conn)s."
msgstr ""

#: cinder/volume/drivers/ibm/gpfs.py:123
#, python-format
msgid "Failed to issue mmgetstate command, error: %s."
msgstr ""

#: cinder/volume/drivers/ibm/gpfs.py:134
#, python-format
msgid "GPFS is not active.  Detailed output: %s."
msgstr ""

#: cinder/volume/drivers/ibm/gpfs.py:147
#, python-format
msgid "Failed to issue df command for path %(path)s, error: %(error)s."
msgstr ""

#: cinder/volume/drivers/ibm/gpfs.py:163 cinder/volume/drivers/ibm/gpfs.py:252
#, python-format
msgid "Failed to issue mmlsconfig command, error: %s."
msgstr ""

#: cinder/volume/drivers/ibm/gpfs.py:174
#, python-format
msgid "Failed to issue mmlsattr command on path %(path)s, error: %(error)s"
msgstr ""

#: cinder/volume/drivers/ibm/gpfs.py:232
#, python-format
msgid "Failed to issue mmlsfs command for path %(path)s, error: %(error)s."
msgstr ""

#: cinder/volume/drivers/ibm/gpfs.py:269
#, python-format
msgid "Failed to issue mmlsattr command for path %(path)s, error: %(error)s."
msgstr ""

#: cinder/volume/drivers/ibm/gpfs.py:803
#, python-format
msgid "Failed to resize volume %(volume_id)s, error: %(error)s."
msgstr ""

#: cinder/volume/drivers/ibm/gpfs.py:877
#, python-format
msgid ""
"Driver-based migration of volume %(vol)s failed. Move from %(src)s to "
"%(dst)s failed with error: %(error)s."
msgstr ""

#: cinder/volume/drivers/ibm/storwize_svc/__init__.py:292
#, python-format
msgid "ensure_export: Volume %s not found on storage"
msgstr ""

#: cinder/volume/drivers/ibm/storwize_svc/__init__.py:311
msgid "The connector does not contain the required information."
msgstr ""

#: cinder/volume/drivers/ibm/storwize_svc/__init__.py:387
#, python-format
msgid "Did not find expected column name in lsvdisk: %s"
msgstr ""

#: cinder/volume/drivers/ibm/storwize_svc/__init__.py:486
#, python-format
msgid ""
"initialize_connection: Failed to collect return properties for volume "
"%(vol)s and connector %(conn)s.\n"
msgstr ""

#: cinder/volume/drivers/ibm/storwize_svc/__init__.py:1032
msgid "Could not get pool data from the storage"
msgstr ""

#: cinder/volume/drivers/ibm/storwize_svc/helpers.py:474
msgid "Protocol must be specified as '<in> iSCSI' or '<in> FC'."
msgstr ""

#: cinder/volume/drivers/ibm/storwize_svc/helpers.py:489
msgid "Replication must be specified as '<is> True' or '<is> False'."
msgstr ""

#: cinder/volume/drivers/ibm/storwize_svc/ssh.py:167
msgid ""
"storwize_svc_multihostmap_enabled is set to False, not allowing multi "
"host mapping."
msgstr ""

#: cinder/volume/drivers/netapp/dataontap/block_base.py:224
#: cinder/volume/drivers/netapp/dataontap/block_base.py:374
#: cinder/volume/drivers/netapp/dataontap/nfs_base.py:105
#: cinder/volume/drivers/netapp/dataontap/nfs_base.py:208
#, python-format
msgid "Resizing %s failed. Cleaning volume."
msgstr ""

#: cinder/volume/drivers/netapp/dataontap/block_base.py:349
#, python-format
msgid "Message: %s"
msgstr ""

#: cinder/volume/drivers/netapp/dataontap/block_base.py:351
#, python-format
msgid "Error getting LUN attribute. Exception: %s"
msgstr ""

#: cinder/volume/drivers/netapp/dataontap/block_base.py:483
#, python-format
msgid "Failure deleting staged tmp LUN %s."
msgstr ""

#: cinder/volume/drivers/netapp/dataontap/block_base.py:486
#, python-format
msgid "Unknown exception in post clone resize LUN %s."
msgstr ""

#: cinder/volume/drivers/netapp/dataontap/block_base.py:488
#, python-format
msgid "Exception details: %s"
msgstr ""

#: cinder/volume/drivers/netapp/dataontap/nfs_7mode.py:94
#, python-format
msgid "Exception creating vol %(name)s on share %(share)s. Details: %(ex)s"
msgstr ""

#: cinder/volume/drivers/netapp/dataontap/nfs_cmode.py:370
#, python-format
msgid "Copy offload workflow unsuccessful. %s"
msgstr ""

#: cinder/volume/drivers/netapp/dataontap/nfs_cmode.py:432
#, python-format
msgid "Error in workflow copy from cache. %s."
msgstr ""

#: cinder/volume/drivers/netapp/dataontap/client/client_base.py:81
#, python-format
msgid "Error provisioning volume %(lun_name)s on %(volume_name)s. Details: %(ex)s"
msgstr ""

#: cinder/volume/drivers/netapp/dataontap/client/client_base.py:184
#, python-format
msgid "LUN %(path)s geometry failed. Message - %(msg)s"
msgstr ""

#: cinder/volume/drivers/netapp/eseries/client.py:75
#, python-format
msgid "Unexpected error while invoking web service. Error - %s."
msgstr ""

#: cinder/volume/drivers/netapp/eseries/iscsi.py:147
#, python-format
msgid "Error resolving host %(host)s. Error - %(e)s."
msgstr ""

#: cinder/volume/drivers/netapp/eseries/iscsi.py:393
#: cinder/volume/drivers/netapp/eseries/iscsi.py:408
#, python-format
msgid "Error creating volume. Msg - %s."
msgstr ""

#: cinder/volume/drivers/netapp/eseries/iscsi.py:431
#, python-format
msgid "Failure deleting snap vol. Error: %s."
msgstr ""

#: cinder/volume/drivers/netapp/eseries/iscsi.py:462
#, python-format
msgid "Vol copy job status %s."
msgstr ""

#: cinder/volume/drivers/nexenta/iscsi.py:202
#: cinder/volume/drivers/nexenta/nfs.py:203
#, python-format
msgid "Volume creation failed, deleting created snapshot %(volume_name)s@%(name)s"
msgstr ""

#: cinder/volume/drivers/nexenta/jsonrpc.py:90
msgid "No headers in server response"
msgstr ""

#: cinder/volume/drivers/prophetstor/dpl_fc.py:58
#, python-format
msgid "Failed to get fiber channel info from storage due to %(stat)s"
msgstr ""

#: cinder/volume/drivers/prophetstor/dpl_fc.py:82
#, python-format
msgid "Failed to get fiber channel target from storage server due to %(stat)s"
msgstr ""

#: cinder/volume/drivers/prophetstor/dpl_fc.py:100
#, python-format
msgid "Failed to get target wwpns from storage due to %(stat)s"
msgstr ""

#: cinder/volume/drivers/prophetstor/dpl_fc.py:118
msgid "Failed to get sns table"
msgstr ""

#: cinder/volume/drivers/prophetstor/dpl_fc.py:147
#, python-format
msgid ""
"Volume %(volumeid)s failed to send assign command, ret: %(status)s "
"output: %(output)s"
msgstr ""

#: cinder/volume/drivers/prophetstor/dpl_fc.py:287
#, python-format
msgid "Failed to export fiber channel target due to %s"
msgstr ""

#: cinder/volume/drivers/prophetstor/dplcommon.py:93
#, python-format
msgid "JSON encode params %(param)s error: %(status)s."
msgstr ""

#: cinder/volume/drivers/prophetstor/dplcommon.py:105
#, python-format
msgid "Connect to Flexvisor error: %s."
msgstr ""

#: cinder/volume/drivers/prophetstor/dplcommon.py:109
#, python-format
msgid "Connect to Flexvisor failed: %s."
msgstr ""

#: cinder/volume/drivers/prophetstor/dplcommon.py:133
#, python-format
msgid "Failed to send request: %s."
msgstr ""

#: cinder/volume/drivers/prophetstor/dplcommon.py:142
msgid "The Flexvisor service is unavailable."
msgstr ""

#: cinder/volume/drivers/prophetstor/dplcommon.py:156
#, python-format
msgid "Failed to get response: %s."
msgstr ""

#: cinder/volume/drivers/prophetstor/dplcommon.py:165
#, python-format
msgid ""
"%(method)s %(url)s unexpected response status: %(response)s (expects: "
"%(expects)s)."
msgstr ""

#: cinder/volume/drivers/prophetstor/dplcommon.py:184
#: cinder/volume/drivers/prophetstor/dplcommon.py:198
#, python-format
msgid "Call to json.loads() raised an exception: %s."
msgstr ""

#: cinder/volume/drivers/prophetstor/dplcommon.py:188
#: cinder/volume/drivers/prophetstor/dplcommon.py:202
#, python-format
msgid "Read response raised an exception: %s."
msgstr ""

#: cinder/volume/drivers/prophetstor/dplcommon.py:765
#, python-format
msgid "Flexvisor failed to get event %(volume)s (%(status)s)."
msgstr ""

#: cinder/volume/drivers/prophetstor/dplcommon.py:1325
#, python-format
msgid "Flexvisor failed to get pool list.(Error: %d)"
msgstr ""

#: cinder/volume/drivers/prophetstor/dplcommon.py:1328
#, python-format
msgid "Flexvisor failed to get pool list due to %s."
msgstr ""

#: cinder/volume/drivers/prophetstor/dplcommon.py:1379
#, python-format
msgid "Failed to get server info due to %(state)s."
msgstr ""

#: cinder/volume/drivers/prophetstor/dplcommon.py:1408
#, python-format
msgid "Flexvisor failed to get pool %(id)s info."
msgstr ""

#: cinder/volume/drivers/san/san.py:151
#: cinder/zonemanager/drivers/brocade/brcd_fc_zone_client_cli.py:417
#: cinder/zonemanager/drivers/cisco/cisco_fc_san_lookup_service.py:269
#: cinder/zonemanager/drivers/cisco/cisco_fc_zone_client_cli.py:397
#, python-format
msgid "Error running SSH command: %s"
msgstr ""

#: cinder/volume/drivers/san/hp/hp_3par_common.py:510
#, python-format
msgid "Error extending volume: %(vol)s. Exception: %(ex)s"
msgstr ""

#: cinder/volume/drivers/san/hp/hp_3par_common.py:883
#, python-format
msgid "Error creating QOS rule %s"
msgstr ""

#: cinder/volume/drivers/san/hp/hp_3par_common.py:1332
#, python-format
msgid "Error extending volume %(id)s. Ex: %(ex)s"
msgstr ""

#: cinder/volume/drivers/san/hp/hp_3par_common.py:1448
#, python-format
msgid "Error attaching volume %s"
msgstr ""

#: cinder/volume/drivers/san/hp/hp_3par_common.py:1456
#, python-format
msgid "Error detaching volume %s"
msgstr ""

#: cinder/volume/drivers/san/hp/hp_3par_common.py:2024
#, python-format
msgid "Exception during snapCPG revert: %s"
msgstr ""

#: cinder/volume/drivers/san/hp/hp_3par_common.py:2092
#, python-format
msgid "Unexpected error when retype() tried to deleteVolumeSet(%s)"
msgstr ""

#: cinder/volume/drivers/san/hp/hp_3par_common.py:2113
#: cinder/volume/drivers/san/hp/hp_3par_common.py:2116
#, python-format
msgid "Unexpected error when retype() revert tried to deleteVolumeSet(%s)"
msgstr ""

#: cinder/volume/drivers/san/hp/hp_3par_common.py:2124
#, python-format
msgid ""
"%(exception)s: Exception during revert of retype for volume "
"%(volume_name)s. Original volume set/QOS settings may not have been fully"
" restored."
msgstr ""

#: cinder/volume/drivers/san/hp/hp_3par_common.py:2135
#, python-format
msgid ""
"%(exception)s: Exception during revert of retype for volume "
"%(volume_name)s. Failed to remove from new volume set %(new_vvs)s."
msgstr ""

#: cinder/volume/drivers/san/hp/hp_3par_iscsi.py:541
#, python-format
msgid "Volume %s doesn't exist on array."
msgstr ""

#: cinder/volume/drivers/san/hp/hp_lefthand_cliq_proxy.py:317
#: cinder/volume/drivers/san/hp/hp_lefthand_rest_proxy.py:207
msgid "Volume did not exist. It will not be deleted"
msgstr ""

#: cinder/volume/drivers/san/hp/hp_lefthand_cliq_proxy.py:329
#: cinder/volume/drivers/san/hp/hp_lefthand_rest_proxy.py:249
msgid "Snapshot did not exist. It will not be deleted"
msgstr ""

#: cinder/volume/drivers/san/hp/hp_lefthand_iscsi.py:91
#, python-format
msgid ""
"Invalid hplefthandclient version found (%(found)s). Version %(minimum)s "
"or greater required."
msgstr ""

#: cinder/volume/drivers/san/hp/hp_lefthand_rest_proxy.py:417
#, python-format
msgid "'%(value)s' is an invalid value for extra spec '%(key)s'"
msgstr ""

#: cinder/volume/drivers/san/hp/hp_msa_common.py:74
#, python-format
msgid "Failed to connect to MSA Array (%(host)s): %(err)s"
msgstr ""

#: cinder/volume/drivers/san/hp/hp_msa_common.py:79
msgid "Failed to log on MSA Array (invalid login?)"
msgstr ""

#: cinder/volume/drivers/san/hp/hp_msa_common.py:133
#, python-format
msgid "%s configuration option is not set"
msgstr ""

#: cinder/volume/drivers/san/hp/hp_msa_common.py:174
msgid "Volume must be detached to perform a clone operation."
msgstr ""

#: cinder/volume/drivers/san/hp/hp_msa_common.py:251
#, python-format
msgid "Unable to get stats for VDisk (%s)"
msgstr ""

#: cinder/volume/drivers/san/hp/hp_msa_common.py:260
msgid "Connector doesn't provide wwpns"
msgstr ""

#: cinder/volume/drivers/violin/v6000_common.py:217
#, python-format
msgid "Lun delete for %s failed!"
msgstr ""

#: cinder/volume/drivers/violin/v6000_common.py:240
#, python-format
msgid "LUN extend for %s failed!"
msgstr ""

#: cinder/volume/drivers/violin/v6000_common.py:266
#, python-format
msgid "LUN snapshot create for %s failed!"
msgstr ""

#: cinder/volume/drivers/violin/v6000_common.py:293
#, python-format
msgid "LUN snapshot delete for %s failed!"
msgstr ""

#: cinder/volume/drivers/violin/v6000_fcp.py:243
#: cinder/volume/drivers/violin/v6000_iscsi.py:321
#, python-format
msgid "LUN export for %s failed!"
msgstr ""

#: cinder/volume/drivers/violin/v6000_fcp.py:274
#: cinder/volume/drivers/violin/v6000_iscsi.py:352
#, python-format
msgid "LUN unexport for %s failed!"
msgstr ""

#: cinder/volume/drivers/violin/v6000_fcp.py:312
#: cinder/volume/drivers/violin/v6000_iscsi.py:392
#, python-format
msgid "Snapshot export for %s failed!"
msgstr ""

#: cinder/volume/drivers/violin/v6000_fcp.py:344
#: cinder/volume/drivers/violin/v6000_iscsi.py:424
#, python-format
msgid "Snapshot unexport for %s failed!"
msgstr ""

#: cinder/volume/drivers/violin/v6000_iscsi.py:246
msgid "Failed to create iscsi target!"
msgstr ""

#: cinder/volume/drivers/violin/v6000_iscsi.py:257
msgid "Failed to bind iSCSI targets!"
msgstr ""

#: cinder/volume/drivers/violin/v6000_iscsi.py:281
msgid "Failed to delete iSCSI target!"
msgstr ""

#: cinder/volume/drivers/vmware/api.py:72
#, python-format
msgid "Failure while invoking function: %(func)s. Error: %(excep)s."
msgstr ""

#: cinder/volume/drivers/vmware/api.py:170
#, python-format
msgid "Error while terminating session: %s."
msgstr ""

#: cinder/volume/drivers/vmware/api.py:190
#, python-format
msgid "Error while logging out from vim session: %s."
msgstr ""

#: cinder/volume/drivers/vmware/api.py:196
#, python-format
msgid "Error while logging out from pbm session: %s."
msgstr ""

#: cinder/volume/drivers/vmware/api.py:313
#: cinder/volume/drivers/vmware/api.py:318
#, python-format
msgid "Task: %(task)s failed with error: %(err)s."
msgstr ""

#: cinder/volume/drivers/vmware/datastore.py:62
#, python-format
msgid "Storage profile: %s cannot be found in vCenter."
msgstr ""

#: cinder/volume/drivers/vmware/datastore.py:213
msgid "Error occurred while selecting datastore."
msgstr ""

#: cinder/volume/drivers/vmware/vmdk.py:961
#, python-format
msgid "Error occurred while copying %(src)s to %(dst)s."
msgstr ""

#: cinder/volume/drivers/vmware/vmdk.py:1023
#, python-format
msgid "Error occurred while copying image: %(image_id)s to %(path)s."
msgstr ""

#: cinder/volume/drivers/vmware/vmdk.py:1148
#, python-format
msgid "Error occurred while creating volume: %(id)s from image: %(image_id)s."
msgstr ""

#: cinder/volume/drivers/vmware/vmdk.py:1216
#, python-format
msgid "Exception in copy_image_to_volume: %s."
msgstr ""

#: cinder/volume/drivers/vmware/vmdk.py:1220
#, python-format
msgid "Deleting the backing: %s"
msgstr ""

#: cinder/volume/drivers/vmware/vmdk.py:1257
#, python-format
msgid "Unable to extend the size of the vmdk virtual disk at the path %s."
msgstr ""

#: cinder/volume/drivers/vmware/vmdk.py:1307
#, python-format
msgid "Exception in copying the image to the volume: %s."
msgstr ""

#: cinder/volume/drivers/vmware/vmdk.py:1509
#, python-format
msgid "Error occurred while cloning backing: %s during retype."
msgstr ""

#: cinder/volume/drivers/vmware/vmdk.py:1573
#, python-format
msgid "Not able to find a different datastore to place the extended volume %s."
msgstr ""

#: cinder/volume/drivers/vmware/vmdk.py:1588
#, python-format
msgid "Not able to relocate volume %s for extending."
msgstr ""

#: cinder/volume/drivers/vmware/vmdk.py:1689
msgid "Error occurred while creating temporary backing."
msgstr ""

#: cinder/volume/drivers/vmware/vmdk.py:1883
#, python-format
msgid "Version string '%s' is not parseable"
msgstr ""

#: cinder/volume/drivers/vmware/vmdk.py:1897
#, python-format
msgid "Not able to configure PBM for VC server: %s"
msgstr ""

#: cinder/volume/drivers/vmware/vmware_images.py:82
msgid "Error occurred during image transfer."
msgstr ""

#: cinder/volume/drivers/vmware/volumeops.py:1206
#, python-format
msgid "Virtual disk device of backing: %s not found."
msgstr ""

#: cinder/volume/drivers/windows/remotefs.py:137
#, python-format
msgid "Could not get share %s capacity info."
msgstr ""

#: cinder/volume/drivers/zfssa/restclient.py:282
#, python-format
msgid "REST Not Available: %s"
msgstr ""

#: cinder/volume/drivers/zfssa/restclient.py:288
#, python-format
msgid "Server Busy retry request: %s"
msgstr ""

#: cinder/volume/drivers/zfssa/restclient.py:294
#, python-format
msgid "Authorizing request: %(zfssaurl)sretry: %(retry)d ."
msgstr ""

#: cinder/volume/drivers/zfssa/restclient.py:311
#, python-format
msgid "URLError: %s"
msgstr ""

#: cinder/volume/drivers/zfssa/webdavclient.py:90
#, python-format
msgid "WebDAV returned with %(code)s error during %(method)s call."
msgstr ""

#: cinder/volume/drivers/zfssa/zfssaiscsi.py:277
#, python-format
msgid "Snapshot %s: has clones"
msgstr ""

#: cinder/volume/drivers/zfssa/zfssaiscsi.py:370
#, python-format
msgid "Clone Volume:%(volume)s failed from source volume:%(src_vref)s"
msgstr ""

#: cinder/volume/drivers/zfssa/zfssanfs.py:168
#, python-format
msgid "Exception during mounting %s."
msgstr ""

#: cinder/volume/drivers/zfssa/zfssarest.py:635
msgid "Error getting initiator groups."
msgstr ""

#: cinder/volume/flows/common.py:60
#, python-format
msgid ""
"Failed setting source volume %(source_volid)s back to its initial "
"%(source_status)s status"
msgstr ""

#: cinder/volume/flows/common.py:93
#: cinder/volume/flows/manager/create_volume.py:699
#, python-format
msgid "Failed updating volume %(volume_id)s with %(update)s"
msgstr ""

#: cinder/volume/flows/api/create_volume.py:529
#, python-format
msgid "Failed destroying volume entry %s"
msgstr ""

#: cinder/volume/flows/api/create_volume.py:613
#, python-format
msgid "Failed rolling back quota for %s reservations"
msgstr ""

#: cinder/volume/flows/api/create_volume.py:659
#, python-format
msgid "Failed to update quota for deleting volume: %s"
msgstr ""

#: cinder/volume/flows/api/create_volume.py:759
#: cinder/volume/flows/manager/create_volume.py:191
#, python-format
msgid "Volume %s: create failed"
msgstr ""

#: cinder/volume/flows/api/create_volume.py:763
msgid "Unexpected build error:"
msgstr ""

#: cinder/volume/flows/manager/create_volume.py:143
#, python-format
msgid "Volume %s: resetting 'creating' status failed."
msgstr ""

#: cinder/volume/flows/manager/create_volume.py:163
#, python-format
msgid "Volume %s: rescheduling failed"
msgstr ""

#: cinder/volume/flows/manager/create_volume.py:319
#, python-format
msgid ""
"Failed notifying about the volume action %(event)s for volume "
"%(volume_id)s"
msgstr ""

#: cinder/volume/flows/manager/create_volume.py:418
#, python-format
msgid ""
"Failed fetching snapshot %(snapshot_id)s bootable flag using the provided"
" glance snapshot %(snapshot_ref_id)s volume reference"
msgstr ""

#: cinder/volume/flows/manager/create_volume.py:435
#, python-format
msgid "Failed updating volume %(volume_id)s bootable flag to true"
msgstr ""

#: cinder/volume/flows/manager/create_volume.py:490
#: cinder/volume/flows/manager/create_volume.py:501
#, python-format
msgid ""
"Failed to copy image %(image_id)s to volume: %(volume_id)s, error: "
"%(error)s"
msgstr ""

#: cinder/volume/flows/manager/create_volume.py:496
#, python-format
msgid "Failed to copy image to volume: %(volume_id)s, error: %(error)s"
msgstr ""

#: cinder/volume/flows/manager/create_volume.py:590
#, python-format
msgid "Failed updating volume %(volume_id)s with %(updates)s"
msgstr ""

#: cinder/volume/flows/manager/create_volume.py:614
#, python-format
msgid "Unable to create volume. Volume driver %s not initialized"
msgstr ""

#: cinder/volume/flows/manager/create_volume.py:656
#: cinder/volume/flows/manager/manage_existing.py:85
#, python-format
msgid ""
"Failed updating model of volume %(volume_id)s with creation provided "
"model %(model)s"
msgstr ""

#: cinder/volume/flows/manager/manage_existing.py:46
#, python-format
msgid "Unable to manage existing volume. Volume driver %s not initialized."
msgstr ""

#: cinder/volume/targets/iscsi.py:187
msgid "The volume driver requires the iSCSI initiator name in the connector."
msgstr ""

#: cinder/volume/targets/lio.py:79
msgid "cinder-rtstool is not installed correctly"
msgstr ""

#: cinder/volume/targets/lio.py:115 cinder/volume/targets/lio.py:124
#, python-format
msgid "Failed to create iscsi target for volume id:%s."
msgstr ""

#: cinder/volume/targets/lio.py:117 cinder/volume/targets/lio.py:143
#, python-format
msgid "%s"
msgstr ""

#: cinder/volume/targets/lio.py:141
#, python-format
msgid "Failed to remove iscsi target for volume id:%s."
msgstr ""

#: cinder/volume/targets/lio.py:170
#, python-format
msgid "Failed to add initiator iqn %s to target"
msgstr ""

#: cinder/volume/targets/lio.py:196
#, python-format
msgid "Failed to delete initiator iqn %s to target."
msgstr ""

#: cinder/volume/targets/tgt.py:111
#, python-format
msgid ""
"Failed to recover attempt to create iscsi backing lun for volume "
"id:%(vol_id)s: %(e)s"
msgstr ""

#: cinder/volume/targets/tgt.py:238
#, python-format
msgid "Failed to create iscsi target for volume id:%(vol_id)s: %(e)s"
msgstr ""

#: cinder/volume/targets/tgt.py:262
#, python-format
msgid ""
"Failed to create iscsi target for volume id:%(vol_id)s. Please ensure "
"your tgtd config file contains 'include %(volumes_dir)s/*'"
msgstr ""

#: cinder/volume/targets/tgt.py:379 cinder/volume/targets/tgt.py:402
#, python-format
msgid "Failed to remove iscsi target for volume id:%(vol_id)s: %(e)s"
msgstr ""

#: cinder/zonemanager/drivers/brocade/brcd_fc_san_lookup_service.py:140
#, python-format
msgid "Failed collecting name server info from fabric %s"
msgstr ""

#: cinder/zonemanager/drivers/brocade/brcd_fc_san_lookup_service.py:199
msgid "Failed collecting nsshow info for fabric"
msgstr ""

#: cinder/zonemanager/drivers/brocade/brcd_fc_san_lookup_service.py:206
msgid "Failed collecting nscamshow"
msgstr ""

#: cinder/zonemanager/drivers/brocade/brcd_fc_zone_client_cli.py:82
#: cinder/zonemanager/drivers/cisco/cisco_fc_zone_client_cli.py:90
#, python-format
msgid "Failed getting active zone set from fabric %s"
msgstr ""

#: cinder/zonemanager/drivers/brocade/brcd_fc_zone_client_cli.py:151
#: cinder/zonemanager/drivers/cisco/cisco_fc_zone_client_cli.py:176
#, python-format
msgid "Deleting zone failed %s"
msgstr ""

#: cinder/zonemanager/drivers/brocade/brcd_fc_zone_client_cli.py:260
#, python-format
msgid "Failed collecting nsshow info for fabric %s"
msgstr ""

#: cinder/zonemanager/drivers/brocade/brcd_fc_zone_client_cli.py:332
msgid "No CLI output for firmware version check"
msgstr ""

#: cinder/zonemanager/drivers/brocade/brcd_fc_zone_client_cli.py:482
#, python-format
msgid "Error executing command via ssh: %s"
msgstr ""

#: cinder/zonemanager/drivers/brocade/brcd_fc_zone_driver.py:363
#, python-format
msgid "Error getting name server info: %s"
msgstr ""

#: cinder/zonemanager/drivers/cisco/cisco_fc_san_lookup_service.py:184
msgid "Failed collecting show fcns database for fabric"
msgstr ""

#: cinder/zonemanager/drivers/cisco/cisco_fc_zone_client_cli.py:225
#, python-format
msgid "Failed getting zone status from fabric %s"
msgstr ""

#: cinder/zonemanager/drivers/cisco/cisco_fc_zone_client_cli.py:306
#, python-format
msgid "Failed collecting fcns database info for fabric %s"
msgstr ""

#: cinder/zonemanager/drivers/cisco/cisco_fc_zone_driver.py:421
#, python-format
msgid "Error getting show fcns database info: %s"
msgstr ""

